2025-05-30 22:59:08,570 ERROR: Exception on /glossary/manage [GET] [in C:\Users\ENVY\AppData\Local\Programs\Python\Python312\Lib\site-packages\flask\app.py:875]
Traceback (most recent call last):
  File "C:\Users\ENVY\AppData\Local\Programs\Python\Python312\Lib\site-packages\flask\app.py", line 1511, in wsgi_app
    response = self.full_dispatch_request()
               ^^^^^^^^^^^^^^^^^^^^^^^^^^^^
  File "C:\Users\ENVY\AppData\Local\Programs\Python\Python312\Lib\site-packages\flask\app.py", line 919, in full_dispatch_request
    rv = self.handle_user_exception(e)
         ^^^^^^^^^^^^^^^^^^^^^^^^^^^^^
  File "C:\Users\ENVY\AppData\Local\Programs\Python\Python312\Lib\site-packages\flask\app.py", line 917, in full_dispatch_request
    rv = self.dispatch_request()
         ^^^^^^^^^^^^^^^^^^^^^^^
  File "C:\Users\ENVY\AppData\Local\Programs\Python\Python312\Lib\site-packages\flask\app.py", line 902, in dispatch_request
    return self.ensure_sync(self.view_functions[rule.endpoint])(**view_args)  # type: ignore[no-any-return]
           ^^^^^^^^^^^^^^^^^^^^^^^^^^^^^^^^^^^^^^^^^^^^^^^^^^^^^^^^^^^^^^^^^
  File "C:\Users\ENVY\AppData\Local\Programs\Python\Python312\Lib\site-packages\flask_login\utils.py", line 290, in decorated_view
    return current_app.ensure_sync(func)(*args, **kwargs)
           ^^^^^^^^^^^^^^^^^^^^^^^^^^^^^^^^^^^^^^^^^^^^^^
  File "C:\Users\ENVY\Desktop\Lernio\app\routes.py", line 157, in manage_glossary
    glossary_items = GlossaryItem.query.order_by(GlossaryItem.word).all()
                     ^^^^^^^^^^^^
NameError: name 'GlossaryItem' is not defined
2025-05-30 22:59:08,621 ERROR: Server Error: 500 Internal Server Error: The server encountered an internal error and was unable to complete your request. Either the server is overloaded or there is an error in the application. [in C:\Users\ENVY\Desktop\Lernio\app\__init__.py:211]
Traceback (most recent call last):
  File "C:\Users\ENVY\AppData\Local\Programs\Python\Python312\Lib\site-packages\flask\app.py", line 1511, in wsgi_app
    response = self.full_dispatch_request()
               ^^^^^^^^^^^^^^^^^^^^^^^^^^^^
  File "C:\Users\ENVY\AppData\Local\Programs\Python\Python312\Lib\site-packages\flask\app.py", line 919, in full_dispatch_request
    rv = self.handle_user_exception(e)
         ^^^^^^^^^^^^^^^^^^^^^^^^^^^^^
  File "C:\Users\ENVY\AppData\Local\Programs\Python\Python312\Lib\site-packages\flask\app.py", line 917, in full_dispatch_request
    rv = self.dispatch_request()
         ^^^^^^^^^^^^^^^^^^^^^^^
  File "C:\Users\ENVY\AppData\Local\Programs\Python\Python312\Lib\site-packages\flask\app.py", line 902, in dispatch_request
    return self.ensure_sync(self.view_functions[rule.endpoint])(**view_args)  # type: ignore[no-any-return]
           ^^^^^^^^^^^^^^^^^^^^^^^^^^^^^^^^^^^^^^^^^^^^^^^^^^^^^^^^^^^^^^^^^
  File "C:\Users\ENVY\AppData\Local\Programs\Python\Python312\Lib\site-packages\flask_login\utils.py", line 290, in decorated_view
    return current_app.ensure_sync(func)(*args, **kwargs)
           ^^^^^^^^^^^^^^^^^^^^^^^^^^^^^^^^^^^^^^^^^^^^^^
  File "C:\Users\ENVY\Desktop\Lernio\app\routes.py", line 157, in manage_glossary
    glossary_items = GlossaryItem.query.order_by(GlossaryItem.word).all()
                     ^^^^^^^^^^^^
NameError: name 'GlossaryItem' is not defined
2025-05-30 22:59:11,144 INFO: Загрузка пользователя с ID: 1 [in C:\Users\ENVY\Desktop\Lernio\app\__init__.py:61]
2025-05-30 22:59:11,146 INFO: Пользователь найден в сессии: 1 [in C:\Users\ENVY\Desktop\Lernio\app\__init__.py:65]
2025-05-30 22:59:11,157 INFO: Загрузка пользователя с ID: 1 [in C:\Users\ENVY\Desktop\Lernio\app\__init__.py:61]
2025-05-30 22:59:11,161 INFO: Пользователь найден в сессии: 1 [in C:\Users\ENVY\Desktop\Lernio\app\__init__.py:65]
2025-05-30 22:59:11,198 INFO: [2025-05-30 22:59:11] User 1: view_teacher_dashboard [in C:\Users\ENVY\Desktop\Lernio\app\utils\__init__.py:35]
2025-05-30 22:59:14,257 INFO: Загрузка пользователя с ID: 4 [in C:\Users\ENVY\Desktop\Lernio\app\__init__.py:61]
2025-05-30 22:59:14,258 INFO: Пользователь найден в сессии: 4 [in C:\Users\ENVY\Desktop\Lernio\app\__init__.py:65]
2025-05-30 22:59:14,266 INFO: Загрузка пользователя с ID: 4 [in C:\Users\ENVY\Desktop\Lernio\app\__init__.py:61]
2025-05-30 22:59:14,266 INFO: Пользователь найден в сессии: 4 [in C:\Users\ENVY\Desktop\Lernio\app\__init__.py:65]
2025-05-30 22:59:14,277 ERROR: Exception on /student/dashboard [GET] [in C:\Users\ENVY\AppData\Local\Programs\Python\Python312\Lib\site-packages\flask\app.py:875]
Traceback (most recent call last):
  File "C:\Users\ENVY\AppData\Local\Programs\Python\Python312\Lib\site-packages\flask\app.py", line 1511, in wsgi_app
    response = self.full_dispatch_request()
               ^^^^^^^^^^^^^^^^^^^^^^^^^^^^
  File "C:\Users\ENVY\AppData\Local\Programs\Python\Python312\Lib\site-packages\flask\app.py", line 919, in full_dispatch_request
    rv = self.handle_user_exception(e)
         ^^^^^^^^^^^^^^^^^^^^^^^^^^^^^
  File "C:\Users\ENVY\AppData\Local\Programs\Python\Python312\Lib\site-packages\flask\app.py", line 917, in full_dispatch_request
    rv = self.dispatch_request()
         ^^^^^^^^^^^^^^^^^^^^^^^
  File "C:\Users\ENVY\AppData\Local\Programs\Python\Python312\Lib\site-packages\flask\app.py", line 902, in dispatch_request
    return self.ensure_sync(self.view_functions[rule.endpoint])(**view_args)  # type: ignore[no-any-return]
           ^^^^^^^^^^^^^^^^^^^^^^^^^^^^^^^^^^^^^^^^^^^^^^^^^^^^^^^^^^^^^^^^^
  File "C:\Users\ENVY\AppData\Local\Programs\Python\Python312\Lib\site-packages\flask_login\utils.py", line 290, in decorated_view
    return current_app.ensure_sync(func)(*args, **kwargs)
           ^^^^^^^^^^^^^^^^^^^^^^^^^^^^^^^^^^^^^^^^^^^^^^
  File "C:\Users\ENVY\Desktop\Lernio\app\student_routes.py", line 21, in decorated_function
    return f(*args, **kwargs)
           ^^^^^^^^^^^^^^^^^^
  File "C:\Users\ENVY\Desktop\Lernio\app\student_routes.py", line 71, in dashboard
    cast(ActivityLog.timestamp, Date).label('date'),
         ^^^^^^^^^^^
NameError: name 'ActivityLog' is not defined
2025-05-30 22:59:14,286 ERROR: Server Error: 500 Internal Server Error: The server encountered an internal error and was unable to complete your request. Either the server is overloaded or there is an error in the application. [in C:\Users\ENVY\Desktop\Lernio\app\__init__.py:211]
Traceback (most recent call last):
  File "C:\Users\ENVY\AppData\Local\Programs\Python\Python312\Lib\site-packages\flask\app.py", line 1511, in wsgi_app
    response = self.full_dispatch_request()
               ^^^^^^^^^^^^^^^^^^^^^^^^^^^^
  File "C:\Users\ENVY\AppData\Local\Programs\Python\Python312\Lib\site-packages\flask\app.py", line 919, in full_dispatch_request
    rv = self.handle_user_exception(e)
         ^^^^^^^^^^^^^^^^^^^^^^^^^^^^^
  File "C:\Users\ENVY\AppData\Local\Programs\Python\Python312\Lib\site-packages\flask\app.py", line 917, in full_dispatch_request
    rv = self.dispatch_request()
         ^^^^^^^^^^^^^^^^^^^^^^^
  File "C:\Users\ENVY\AppData\Local\Programs\Python\Python312\Lib\site-packages\flask\app.py", line 902, in dispatch_request
    return self.ensure_sync(self.view_functions[rule.endpoint])(**view_args)  # type: ignore[no-any-return]
           ^^^^^^^^^^^^^^^^^^^^^^^^^^^^^^^^^^^^^^^^^^^^^^^^^^^^^^^^^^^^^^^^^
  File "C:\Users\ENVY\AppData\Local\Programs\Python\Python312\Lib\site-packages\flask_login\utils.py", line 290, in decorated_view
    return current_app.ensure_sync(func)(*args, **kwargs)
           ^^^^^^^^^^^^^^^^^^^^^^^^^^^^^^^^^^^^^^^^^^^^^^
  File "C:\Users\ENVY\Desktop\Lernio\app\student_routes.py", line 21, in decorated_function
    return f(*args, **kwargs)
           ^^^^^^^^^^^^^^^^^^
  File "C:\Users\ENVY\Desktop\Lernio\app\student_routes.py", line 71, in dashboard
    cast(ActivityLog.timestamp, Date).label('date'),
         ^^^^^^^^^^^
NameError: name 'ActivityLog' is not defined
2025-05-30 22:59:15,158 INFO: Загрузка пользователя с ID: 4 [in C:\Users\ENVY\Desktop\Lernio\app\__init__.py:61]
2025-05-30 22:59:15,158 INFO: Пользователь найден в сессии: 4 [in C:\Users\ENVY\Desktop\Lernio\app\__init__.py:65]
2025-05-30 22:59:15,170 INFO: Загрузка пользователя с ID: 4 [in C:\Users\ENVY\Desktop\Lernio\app\__init__.py:61]
2025-05-30 22:59:15,171 INFO: Пользователь найден в сессии: 4 [in C:\Users\ENVY\Desktop\Lernio\app\__init__.py:65]
2025-05-30 22:59:15,182 ERROR: Exception on /student/dashboard [GET] [in C:\Users\ENVY\AppData\Local\Programs\Python\Python312\Lib\site-packages\flask\app.py:875]
Traceback (most recent call last):
  File "C:\Users\ENVY\AppData\Local\Programs\Python\Python312\Lib\site-packages\flask\app.py", line 1511, in wsgi_app
    response = self.full_dispatch_request()
               ^^^^^^^^^^^^^^^^^^^^^^^^^^^^
  File "C:\Users\ENVY\AppData\Local\Programs\Python\Python312\Lib\site-packages\flask\app.py", line 919, in full_dispatch_request
    rv = self.handle_user_exception(e)
         ^^^^^^^^^^^^^^^^^^^^^^^^^^^^^
  File "C:\Users\ENVY\AppData\Local\Programs\Python\Python312\Lib\site-packages\flask\app.py", line 917, in full_dispatch_request
    rv = self.dispatch_request()
         ^^^^^^^^^^^^^^^^^^^^^^^
  File "C:\Users\ENVY\AppData\Local\Programs\Python\Python312\Lib\site-packages\flask\app.py", line 902, in dispatch_request
    return self.ensure_sync(self.view_functions[rule.endpoint])(**view_args)  # type: ignore[no-any-return]
           ^^^^^^^^^^^^^^^^^^^^^^^^^^^^^^^^^^^^^^^^^^^^^^^^^^^^^^^^^^^^^^^^^
  File "C:\Users\ENVY\AppData\Local\Programs\Python\Python312\Lib\site-packages\flask_login\utils.py", line 290, in decorated_view
    return current_app.ensure_sync(func)(*args, **kwargs)
           ^^^^^^^^^^^^^^^^^^^^^^^^^^^^^^^^^^^^^^^^^^^^^^
  File "C:\Users\ENVY\Desktop\Lernio\app\student_routes.py", line 21, in decorated_function
    return f(*args, **kwargs)
           ^^^^^^^^^^^^^^^^^^
  File "C:\Users\ENVY\Desktop\Lernio\app\student_routes.py", line 71, in dashboard
    cast(ActivityLog.timestamp, Date).label('date'),
         ^^^^^^^^^^^
NameError: name 'ActivityLog' is not defined
