2025-05-30 22:57:43,932 ERROR: Server Error: 500 Internal Server Error: The server encountered an internal error and was unable to complete your request. Either the server is overloaded or there is an error in the application. [in C:\Users\ENVY\Desktop\Lernio\app\__init__.py:211]
Traceback (most recent call last):
  File "C:\Users\ENVY\AppData\Local\Programs\Python\Python312\Lib\site-packages\flask\app.py", line 1511, in wsgi_app
    response = self.full_dispatch_request()
               ^^^^^^^^^^^^^^^^^^^^^^^^^^^^
  File "C:\Users\ENVY\AppData\Local\Programs\Python\Python312\Lib\site-packages\flask\app.py", line 919, in full_dispatch_request
    rv = self.handle_user_exception(e)
         ^^^^^^^^^^^^^^^^^^^^^^^^^^^^^
  File "C:\Users\ENVY\AppData\Local\Programs\Python\Python312\Lib\site-packages\flask\app.py", line 917, in full_dispatch_request
    rv = self.dispatch_request()
         ^^^^^^^^^^^^^^^^^^^^^^^
  File "C:\Users\ENVY\AppData\Local\Programs\Python\Python312\Lib\site-packages\flask\app.py", line 902, in dispatch_request
    return self.ensure_sync(self.view_functions[rule.endpoint])(**view_args)  # type: ignore[no-any-return]
           ^^^^^^^^^^^^^^^^^^^^^^^^^^^^^^^^^^^^^^^^^^^^^^^^^^^^^^^^^^^^^^^^^
  File "C:\Users\ENVY\AppData\Local\Programs\Python\Python312\Lib\site-packages\flask_login\utils.py", line 290, in decorated_view
    return current_app.ensure_sync(func)(*args, **kwargs)
           ^^^^^^^^^^^^^^^^^^^^^^^^^^^^^^^^^^^^^^^^^^^^^^
  File "C:\Users\ENVY\Desktop\Lernio\app\student_routes.py", line 21, in decorated_function
    return f(*args, **kwargs)
           ^^^^^^^^^^^^^^^^^^
  File "C:\Users\ENVY\Desktop\Lernio\app\student_routes.py", line 71, in dashboard
    cast(ActivityLog.timestamp, Date).label('date'),
         ^^^^^^^^^^^
NameError: name 'ActivityLog' is not defined
2025-05-30 22:57:44,013 INFO: Загрузка пользователя с ID: 4 [in C:\Users\ENVY\Desktop\Lernio\app\__init__.py:61]
2025-05-30 22:57:44,014 INFO: Пользователь найден в сессии: 4 [in C:\Users\ENVY\Desktop\Lernio\app\__init__.py:65]
2025-05-30 22:57:44,024 INFO: Загрузка пользователя с ID: 4 [in C:\Users\ENVY\Desktop\Lernio\app\__init__.py:61]
2025-05-30 22:57:44,024 INFO: Пользователь найден в сессии: 4 [in C:\Users\ENVY\Desktop\Lernio\app\__init__.py:65]
2025-05-30 22:57:44,044 ERROR: Exception on /student/dashboard [GET] [in C:\Users\ENVY\AppData\Local\Programs\Python\Python312\Lib\site-packages\flask\app.py:875]
Traceback (most recent call last):
  File "C:\Users\ENVY\AppData\Local\Programs\Python\Python312\Lib\site-packages\flask\app.py", line 1511, in wsgi_app
    response = self.full_dispatch_request()
               ^^^^^^^^^^^^^^^^^^^^^^^^^^^^
  File "C:\Users\ENVY\AppData\Local\Programs\Python\Python312\Lib\site-packages\flask\app.py", line 919, in full_dispatch_request
    rv = self.handle_user_exception(e)
         ^^^^^^^^^^^^^^^^^^^^^^^^^^^^^
  File "C:\Users\ENVY\AppData\Local\Programs\Python\Python312\Lib\site-packages\flask\app.py", line 917, in full_dispatch_request
    rv = self.dispatch_request()
         ^^^^^^^^^^^^^^^^^^^^^^^
  File "C:\Users\ENVY\AppData\Local\Programs\Python\Python312\Lib\site-packages\flask\app.py", line 902, in dispatch_request
    return self.ensure_sync(self.view_functions[rule.endpoint])(**view_args)  # type: ignore[no-any-return]
           ^^^^^^^^^^^^^^^^^^^^^^^^^^^^^^^^^^^^^^^^^^^^^^^^^^^^^^^^^^^^^^^^^
  File "C:\Users\ENVY\AppData\Local\Programs\Python\Python312\Lib\site-packages\flask_login\utils.py", line 290, in decorated_view
    return current_app.ensure_sync(func)(*args, **kwargs)
           ^^^^^^^^^^^^^^^^^^^^^^^^^^^^^^^^^^^^^^^^^^^^^^
  File "C:\Users\ENVY\Desktop\Lernio\app\student_routes.py", line 21, in decorated_function
    return f(*args, **kwargs)
           ^^^^^^^^^^^^^^^^^^
  File "C:\Users\ENVY\Desktop\Lernio\app\student_routes.py", line 71, in dashboard
    cast(ActivityLog.timestamp, Date).label('date'),
         ^^^^^^^^^^^
NameError: name 'ActivityLog' is not defined
2025-05-30 22:57:44,059 ERROR: Server Error: 500 Internal Server Error: The server encountered an internal error and was unable to complete your request. Either the server is overloaded or there is an error in the application. [in C:\Users\ENVY\Desktop\Lernio\app\__init__.py:211]
Traceback (most recent call last):
  File "C:\Users\ENVY\AppData\Local\Programs\Python\Python312\Lib\site-packages\flask\app.py", line 1511, in wsgi_app
    response = self.full_dispatch_request()
               ^^^^^^^^^^^^^^^^^^^^^^^^^^^^
  File "C:\Users\ENVY\AppData\Local\Programs\Python\Python312\Lib\site-packages\flask\app.py", line 919, in full_dispatch_request
    rv = self.handle_user_exception(e)
         ^^^^^^^^^^^^^^^^^^^^^^^^^^^^^
  File "C:\Users\ENVY\AppData\Local\Programs\Python\Python312\Lib\site-packages\flask\app.py", line 917, in full_dispatch_request
    rv = self.dispatch_request()
         ^^^^^^^^^^^^^^^^^^^^^^^
  File "C:\Users\ENVY\AppData\Local\Programs\Python\Python312\Lib\site-packages\flask\app.py", line 902, in dispatch_request
    return self.ensure_sync(self.view_functions[rule.endpoint])(**view_args)  # type: ignore[no-any-return]
           ^^^^^^^^^^^^^^^^^^^^^^^^^^^^^^^^^^^^^^^^^^^^^^^^^^^^^^^^^^^^^^^^^
  File "C:\Users\ENVY\AppData\Local\Programs\Python\Python312\Lib\site-packages\flask_login\utils.py", line 290, in decorated_view
    return current_app.ensure_sync(func)(*args, **kwargs)
           ^^^^^^^^^^^^^^^^^^^^^^^^^^^^^^^^^^^^^^^^^^^^^^
  File "C:\Users\ENVY\Desktop\Lernio\app\student_routes.py", line 21, in decorated_function
    return f(*args, **kwargs)
           ^^^^^^^^^^^^^^^^^^
  File "C:\Users\ENVY\Desktop\Lernio\app\student_routes.py", line 71, in dashboard
    cast(ActivityLog.timestamp, Date).label('date'),
         ^^^^^^^^^^^
NameError: name 'ActivityLog' is not defined
2025-05-30 22:57:44,377 INFO: Загрузка пользователя с ID: 4 [in C:\Users\ENVY\Desktop\Lernio\app\__init__.py:61]
2025-05-30 22:57:44,378 INFO: Пользователь найден в сессии: 4 [in C:\Users\ENVY\Desktop\Lernio\app\__init__.py:65]
2025-05-30 22:57:44,397 INFO: Загрузка пользователя с ID: 4 [in C:\Users\ENVY\Desktop\Lernio\app\__init__.py:61]
2025-05-30 22:57:44,399 INFO: Пользователь найден в сессии: 4 [in C:\Users\ENVY\Desktop\Lernio\app\__init__.py:65]
2025-05-30 22:57:44,421 ERROR: Exception on /student/dashboard [GET] [in C:\Users\ENVY\AppData\Local\Programs\Python\Python312\Lib\site-packages\flask\app.py:875]
Traceback (most recent call last):
  File "C:\Users\ENVY\AppData\Local\Programs\Python\Python312\Lib\site-packages\flask\app.py", line 1511, in wsgi_app
    response = self.full_dispatch_request()
               ^^^^^^^^^^^^^^^^^^^^^^^^^^^^
  File "C:\Users\ENVY\AppData\Local\Programs\Python\Python312\Lib\site-packages\flask\app.py", line 919, in full_dispatch_request
    rv = self.handle_user_exception(e)
         ^^^^^^^^^^^^^^^^^^^^^^^^^^^^^
  File "C:\Users\ENVY\AppData\Local\Programs\Python\Python312\Lib\site-packages\flask\app.py", line 917, in full_dispatch_request
    rv = self.dispatch_request()
         ^^^^^^^^^^^^^^^^^^^^^^^
  File "C:\Users\ENVY\AppData\Local\Programs\Python\Python312\Lib\site-packages\flask\app.py", line 902, in dispatch_request
    return self.ensure_sync(self.view_functions[rule.endpoint])(**view_args)  # type: ignore[no-any-return]
           ^^^^^^^^^^^^^^^^^^^^^^^^^^^^^^^^^^^^^^^^^^^^^^^^^^^^^^^^^^^^^^^^^
  File "C:\Users\ENVY\AppData\Local\Programs\Python\Python312\Lib\site-packages\flask_login\utils.py", line 290, in decorated_view
    return current_app.ensure_sync(func)(*args, **kwargs)
           ^^^^^^^^^^^^^^^^^^^^^^^^^^^^^^^^^^^^^^^^^^^^^^
  File "C:\Users\ENVY\Desktop\Lernio\app\student_routes.py", line 21, in decorated_function
    return f(*args, **kwargs)
           ^^^^^^^^^^^^^^^^^^
  File "C:\Users\ENVY\Desktop\Lernio\app\student_routes.py", line 71, in dashboard
    cast(ActivityLog.timestamp, Date).label('date'),
         ^^^^^^^^^^^
NameError: name 'ActivityLog' is not defined
2025-05-30 22:57:44,439 ERROR: Server Error: 500 Internal Server Error: The server encountered an internal error and was unable to complete your request. Either the server is overloaded or there is an error in the application. [in C:\Users\ENVY\Desktop\Lernio\app\__init__.py:211]
Traceback (most recent call last):
  File "C:\Users\ENVY\AppData\Local\Programs\Python\Python312\Lib\site-packages\flask\app.py", line 1511, in wsgi_app
    response = self.full_dispatch_request()
               ^^^^^^^^^^^^^^^^^^^^^^^^^^^^
  File "C:\Users\ENVY\AppData\Local\Programs\Python\Python312\Lib\site-packages\flask\app.py", line 919, in full_dispatch_request
    rv = self.handle_user_exception(e)
         ^^^^^^^^^^^^^^^^^^^^^^^^^^^^^
  File "C:\Users\ENVY\AppData\Local\Programs\Python\Python312\Lib\site-packages\flask\app.py", line 917, in full_dispatch_request
    rv = self.dispatch_request()
         ^^^^^^^^^^^^^^^^^^^^^^^
  File "C:\Users\ENVY\AppData\Local\Programs\Python\Python312\Lib\site-packages\flask\app.py", line 902, in dispatch_request
    return self.ensure_sync(self.view_functions[rule.endpoint])(**view_args)  # type: ignore[no-any-return]
           ^^^^^^^^^^^^^^^^^^^^^^^^^^^^^^^^^^^^^^^^^^^^^^^^^^^^^^^^^^^^^^^^^
  File "C:\Users\ENVY\AppData\Local\Programs\Python\Python312\Lib\site-packages\flask_login\utils.py", line 290, in decorated_view
    return current_app.ensure_sync(func)(*args, **kwargs)
           ^^^^^^^^^^^^^^^^^^^^^^^^^^^^^^^^^^^^^^^^^^^^^^
  File "C:\Users\ENVY\Desktop\Lernio\app\student_routes.py", line 21, in decorated_function
    return f(*args, **kwargs)
           ^^^^^^^^^^^^^^^^^^
  File "C:\Users\ENVY\Desktop\Lernio\app\student_routes.py", line 71, in dashboard
    cast(ActivityLog.timestamp, Date).label('date'),
         ^^^^^^^^^^^
NameError: name 'ActivityLog' is not defined
2025-05-30 22:57:44,716 INFO: Загрузка пользователя с ID: 4 [in C:\Users\ENVY\Desktop\Lernio\app\__init__.py:61]
2025-05-30 22:57:44,716 INFO: Пользователь найден в сессии: 4 [in C:\Users\ENVY\Desktop\Lernio\app\__init__.py:65]
